Workbook

Sheet 00_사용안내
A1: GearMatch AI — 06-A Product Recommendation DB v0.2
A3: 항목 | B3: 값 | D3: KPI | E3: 값
A4: 생성 기준일 | B4: 2026-08-28 | D4: 전체 Product | E4: 61
A5: 기준 문서 | B5: 06_데이터 기획서 v0.1 | D5: KR 판매 근거 Product | E5: 51
A6: Migration 원천 | B6: 러닝화_DB_통합본.xlsx | D6: Target 30 | E6: 30
A7: Review 원천 | B7: 국내_러닝화_리뷰.xlsx + 해외_러닝화_리뷰.xlsx | D7: Recommendation Eligible | E7: 29
A8: Product 단위 | B8: 1 Row = 1 Product Model + Version | D8: Review Evidence 행 | E8: 275
A9: 원칙 | B9: Source 없는 값/AI 임의 점수 생성 금지
A11: 현재 상태 해석
A12: v0.2에서는 한국 MVP Target 30개를 대상으로 성능/설계 데이터를 보강했습니다. 29개는 Cushion·Stability·Responsiveness·Weight·Drop·Plate·Fit·Wide·Level·Distance의 P0 필드를 채웠으며, adidas Duramo SL 2는 공식 Fact는 확인했지만 비교 가능한 독립 성능 점수가 없어 Recommendation Eligible에서 제외했습니다. 성능 비교는 RTINGS 동일 테스트 벤치를 우선하고, 미커버 제품은 RunRepeat 상대 측정을 Tier B로 분리했습니다.
A18: Sheet | B18: 용도
A19: 01_Product_Master | B19: 제품 식별 / 시장 / 공식 가격 / Target30 / Eligibility
A20: 02_Recommendation_Attrs | B20: 추천 계산용 Attribute / Caution / Missing 관리
A21: 03_Product_Evidence | B21: Field 단위 Source / Review / Lab Evidence
A22: 04_Target30_Gaps | B22: Target 30 완료 상태 및 추가 조사 항목
A23: 05_v0.2_Benchmark | B23: 성능 원점수·정규화·Source Tier·Confidence
A24: 06_v0.2_Release_Notes | B24: v0.2 정규화 규칙·운영 권고·주의사항
A25: 99_Codebook | B25: Controlled Vocabulary / Rule Version / Data Policy
A26: v0.2 Research Status
A27: Target 30 | B27: 30 | D27: Tier A / RTINGS | E27: 26 | G27: Score Rule | H27: PERF_NORM_v0.2
A28: Ready for MVP | B28: 29 | D28: Tier B / RunRepeat | E28: 3 | G28: Verified at | H28: 2026-08-28
A29: Research Required | B29: 1 | D29: Tier C / Official only | E29: 1 | G29: Pending Product | H29: adidas Duramo SL 2
A31: 다음 작업: Duramo SL 2의 독립 비교 데이터 확보 후 Target 30을 모두 Eligible로 전환하고, Recommendation Logic Spec에서 Source Tier / Confidence를 가중치에 반영합니다.

Sheet 01_Product_Master
A1: product_id | B1: brand | C1: brand_ko | D1: series | E1: model_name | F1: version | G1: display_name | H1: market | I1: currency | J1: product_status | K1: kr_sale_confirmed | L1: official_product_url | M1: official_image_url | N1: image_reference_url | O1: msrp_krw_or_source_currency | P1: msrp_raw | Q1: price_verified_at | R1: target_30 | S1: recommendation_eligible | T1: data_status | U1: product_data_version | V1: legacy_use_category | W1: legacy_description | X1: source_quality_note | Y1: updated_at
A2: GM-NK-PEGASUS-42 | B2: Nike | C2: 나이키 | D2: Pegasus | E2: Pegasus | F2: 42 | G2: Nike Pegasus 42 | H2: KR | I2: KRW | J2: CURRENT | K2: TRUE | L2: https://www.nike.com/kr/w/pegasus-running-shoes-37v7jz8nexhzy7ok | N2: https://www.nike.com/kr/w/pegasus-running-shoes-37v7jz8nexhzy7ok | O2: 169000 | P2: 169,000원 | Q2: 2026-07-01 | R2: TRUE | S2: =AND(H2="KR",K2=TRUE,O2<>"",IFERROR(VLOOKUP(A2,'02_Recommendation_Attrs'!$A$2:$W$100,23,FALSE),FALSE),IFERROR(VLOOKUP(A2,'05_v0.2_Benchmark'!$A$2:$AC$31,29,FALSE),FALSE)) -> TRUE | T2: VERIFIED | U2: PDB_v0.2 | V2: 데일리/올라운드 | W2: 올라운드 데일리 트레이너. 입문~중급 러너의 조깅, 기본 훈련, 가벼운 스피드런까지 무난하게 커버. | X2: DIRECT_IMAGE_URL_NOT_VERIFIED | Y2: 2026-08-28
A3: GM-NK-VOMERO-18 | B3: Nike | C3: 나이키 | D3: Vomero | E3: Vomero | F3: 18 | G3: Nike Vomero 18 | H3: KR | I3: KRW | J3: CURRENT | K3: TRUE | L3: https://www.nike.com/kr/w/vomero-running-shoes-37v7jz7gee1zy7ok | N3: https://www.nike.com/kr/w/vomero-running-shoes-37v7jz7gee1zy7ok | O3: 189000 | P3: Vomero 18 189,000원 / Plus 219,000원 / Premium 299,000원 | Q3: 2026-07-01 | R3: TRUE | S3: =AND(H3="KR",K3=TRUE,O3<>"",IFERROR(VLOOKUP(A3,'02_Recommendation_Attrs'!$A$2:$W$100,23,FALSE),FALSE),IFERROR(VLOOKUP(A3,'05_v0.2_Benchmark'!$A$2:$AC$31,29,FALSE),FALSE)) -> TRUE | T3: VERIFIED | U3: PDB_v0.2 | V3: 쿠션/장거리 | W3: 쿠셔닝 중심의 편안한 데일리·장거리용. 부드러운 착지감과 보호감을 선호하는 러너에게 적합. | X3: CATEGORY_OR_SHARED_URL;DIRECT_IMAGE_URL_NOT_VERIFIED | Y3: 2026-08-28
A4: GM-NK-VOMERO-PLUS-BASE | B4: Nike | C4: 나이키 | D4: Vomero | E4: Vomero Plus | G4: Nike Vomero Plus | H4: KR | I4: KRW | J4: CURRENT | K4: TRUE | L4: https://www.nike.com/kr/w/vomero-running-shoes-37v7jz7gee1zy7ok | N4: https://www.nike.com/kr/w/vomero-running-shoes-37v7jz7gee1zy7ok | O4: 219000 | P4: Vomero 18 189,000원 / Plus 219,000원 / Premium 299,000원 | Q4: 2026-07-01 | R4: FALSE | S4: =IFERROR(VLOOKUP(A4,'02_Recommendation_Attrs'!$A$2:$W$100,23,FALSE),FALSE) -> FALSE | T4: DRAFT | U4: PDB_v0.1 | V4: 쿠션/장거리 | W4: 쿠셔닝 중심의 편안한 데일리·장거리용. 부드러운 착지감과 보호감을 선호하는 러너에게 적합. | X4: CATEGORY_OR_SHARED_URL;DIRECT_IMAGE_URL_NOT_VERIFIED | Y4: 2026-08-28
A5: GM-NK-VOMERO-PREMIUM-BASE | B5: Nike | C5: 나이키 | D5: Vomero | E5: Vomero Premium | G5: Nike Vomero Premium | H5: KR | I5: KRW | J5: CURRENT | K5: TRUE | L5: https://www.nike.com/kr/w/vomero-running-shoes-37v7jz7gee1zy7ok | N5: https://www.nike.com/kr/w/vomero-running-shoes-37v7jz7gee1zy7ok | O5: 299000 | P5: Vomero 18 189,000원 / Plus 219,000원 / Premium 299,000원 | Q5: 2026-07-01 | R5: FALSE | S5: =IFERROR(VLOOKUP(A5,'02_Recommendation_Attrs'!$A$2:$W$100,23,FALSE),FALSE) -> FALSE | T5: DRAFT | U5: PDB_v0.1 | V5: 쿠션/장거리 | W5: 쿠셔닝 중심의 편안한 데일리·장거리용. 부드러운 착지감과 보호감을 선호하는 러너에게 적합. | X5: CATEGORY_OR_SHARED_URL;DIRECT_IMAGE_URL_NOT_VERIFIED | Y5: 2026-08-28
A6: GM-NK-STRUCTURE-26 | B6: Nike | C6: 나이키 | D6: Structure | E6: Structure | F6: 26 | G6: Nike Structure 26 | H6: KR | I6: KRW | J6: CURRENT | K6: TRUE | L6: https://www.nike.com/kr/w/structure-running-shoes-1sytgz37v7jzy7ok | N6: https://www.nike.com/kr/w/structure-running-shoes-1sytgz37v7jzy7ok | O6: 169000 | P6: Structure 26 169,000원 / Structure Plus 209,000~219,000원 | Q6: 2026-07-01 | R6: TRUE | S6: =AND(H6="KR",K6=TRUE,O6<>"",IFERROR(VLOOKUP(A6,'02_Recommendation_Attrs'!$A$2:$W$100,23,FALSE),FALSE),IFERROR(VLOOKUP(A6,'05_v0.2_Benchmark'!$A$2:$AC$31,29,FALSE),FALSE)) -> TRUE | T6: VERIFIED | U6: PDB_v0.2 | V6: 안정화 | W6: 안정성 중심 데일리 러닝화. 발이 안쪽으로 무너지는 느낌이 있거나 안정감을 원하는 러너에게 적합. | X6: CATEGORY_OR_SHARED_URL;DIRECT_IMAGE_URL_NOT_VERIFIED | Y6: 2026-08-28
A7: GM-NK-STRUCTURE-PLUS-BASE | B7: Nike | C7: 나이키 | D7: Structure | E7: Structure Plus | G7: Nike Structure Plus | H7: KR | I7: KRW | J7: CURRENT | K7: TRUE | L7: https://www.nike.com/kr/w/structure-running-shoes-1sytgz37v7jzy7ok | N7: https://www.nike.com/kr/w/structure-running-shoes-1sytgz37v7jzy7ok | P7: Structure 26 169,000원 / Structure Plus 209,000~219,000원 | Q7: 2026-07-01 | R7: FALSE | S7: =IFERROR(VLOOKUP(A7,'02_Recommendation_Attrs'!$A$2:$W$100,23,FALSE),FALSE) -> FALSE | T7: DRAFT | U7: PDB_v0.1 | V7: 안정화 | W7: 안정성 중심 데일리 러닝화. 발이 안쪽으로 무너지는 느낌이 있거나 안정감을 원하는 러너에게 적합. | X7: EXACT_MSRP_MISSING;CATEGORY_OR_SHARED_URL;DIRECT_IMAGE_URL_NOT_VERIFIED | Y7: 2026-08-28
A8: GM-NK-ZOOM-FLY-6 | B8: Nike | C8: 나이키 | D8: Zoom Fly | E8: Zoom Fly | F8: 6 | G8: Nike Zoom Fly 6 | H8: KR | I8: KRW | J8: CURRENT | K8: TRUE | L8: https://www.nike.com/kr/w/zoom-fly-running-shoes-37v7jz7oc5azy7ok | N8: https://www.nike.com/kr/w/zoom-fly-running-shoes-37v7jz7oc5azy7ok | P8: 209,000~229,000원 | Q8: 2026-07-01 | R8: FALSE | S8: =IFERROR(VLOOKUP(A8,'02_Recommendation_Attrs'!$A$2:$W$100,23,FALSE),FALSE) -> FALSE | T8: DRAFT | U8: PDB_v0.1 | V8: 템포/스피드훈련 | W8: 템포·레이싱 훈련용. 반발력과 추진감을 활용해 빠른 페이스 훈련에 적합. | X8: EXACT_MSRP_MISSING;DIRECT_IMAGE_URL_NOT_VERIFIED | Y8: 2026-08-28
A9: GM-NK-ALPHAFLY-3 | B9: Nike | C9: 나이키 | D9: Alphafly | E9: Alphafly | F9: 3 | G9: Nike Alphafly 3 | H9: KR | I9: KRW | J9: CURRENT | K9: TRUE | L9: https://www.nike.com/kr/w/alphafly-1tp17z38l5kz77ghy | N9: https://www.nike.com/kr/w/alphafly-1tp17z38l5kz77ghy | P9: 339,000~359,000원 | Q9: 2026-07-01 | R9: FALSE | S9: =IFERROR(VLOOKUP(A9,'02_Recommendation_Attrs'!$A$2:$W$100,23,FALSE),FALSE) -> FALSE | T9: DRAFT | U9: PDB_v0.1 | V9: 레이스/카본 | W9: 레이스용 최상급 카본 슈즈. 마라톤 기록 단축과 대회용 목적에 적합. | X9: EXACT_MSRP_MISSING;DIRECT_IMAGE_URL_NOT_VERIFIED | Y9: 2026-08-28
A10: GM-AD-ULTRABOOST-5X | B10: adidas | C10: 아디다스 | D10: Ultraboost | E10: Ultraboost | F10: 5X | G10: adidas Ultraboost 5X | H10: KR | I10: KRW | J10: CURRENT | K10: TRUE | L10: https://www.adidas.co.kr/ultraboost | N10: https://www.adidas.co.kr/ultraboost | P10: 정가 199,000~329,000원 / 일부 세일 153,300원~ | Q10: 2026-07-02 | R10: FALSE | S10: =IFERROR(VLOOKUP(A10,'02_Recommendation_Attrs'!$A$2:$W$100,23,FALSE),FALSE) -> FALSE | T10: DRAFT | U10: PDB_v0.1 | V10: 쿠션/라이프스타일 | W10: 프리미엄 쿠션과 일상 겸용성이 강한 라인. 장거리·회복 러닝과 라이프스타일 겸용에 적합. | X10: EXACT_MSRP_MISSING;CATEGORY_OR_SHARED_URL;DIRECT_IMAGE_URL_NOT_VERIFIED | Y10: 2026-08-28
A11: GM-AD-ULTRABOOST-1-0-ATR-BASE | B11: adidas | C11: 아디다스 | D11: Ultraboost | E11: Ultraboost 1.0 ATR | G11: adidas Ultraboost 1.0 ATR | H11: KR | I11: KRW | J11: CURRENT | K11: TRUE | L11: https://www.adidas.co.kr/ultraboost | N11: https://www.adidas.co.kr/ultraboost | P11: 정가 199,000~329,000원 / 일부 세일 153,300원~ | Q11: 2026-07-02 | R11: FALSE | S11: =IFERROR(VLOOKUP(A11,'02_Recommendation_Attrs'!$A$2:$W$100,23,FALSE),FALSE) -> FALSE | T11: DRAFT | U11: PDB_v0.1 | V11: 쿠션/라이프스타일 | W11: 프리미엄 쿠션과 일상 겸용성이 강한 라인. 장거리·회복 러닝과 라이프스타일 겸용에 적합. | X11: EXACT_MSRP_MISSING;CATEGORY_OR_SHARED_URL;DIRECT_IMAGE_URL_NOT_VERIFIED | Y11: 2026-08-28
A12: GM-AD-SUPERNOVA-RISE-3 | B12: adidas | C12: 아디다스 | D12: Supernova | E12: Supernova Rise | F12: 3 | G12: adidas Supernova Rise 3 | H12: KR | I12: KRW | J12: CURRENT | K12: TRUE | L12: https://www.adidas.co.kr/supernova-running-shoes | N12: https://www.adidas.co.kr/supernova-running-shoes | O12: 159000 | P12: Supernova Rise 3 159,000원 / Ease 99,000~119,000원 / 협업 모델 189,000원 | Q12: 2026-07-01 | R12: TRUE | S12: =AND(H12="KR",K12=TRUE,O12<>"",IFERROR(VLOOKUP(A12,'02_Recommendation_Attrs'!$A$2:$W$100,23,FALSE),FALSE),IFERROR(VLOOKUP(A12,'05_v0.2_Benchmark'!$A$2:$AC$31,29,FALSE),FALSE)) -> TRUE | T12: VERIFIED | U12: PDB_v0.2 | V12: 데일리/입문 | W12: 입문자부터 일반 러너까지 편안함과 안정감을 중시하는 데일리 러닝화. | X12: CATEGORY_OR_SHARED_URL;DIRECT_IMAGE_URL_NOT_VERIFIED | Y12: 2026-08-28
A13: GM-AD-SUPERNOVA-EASE-BASE | B13: adidas | C13: 아디다스 | D13: Supernova | E13: Supernova Ease | G13: adidas Supernova Ease | H13: KR | I13: KRW | J13: CURRENT | K13: TRUE | L13: https://www.adidas.co.kr/supernova-running-shoes | N13: https://www.adidas.co.kr/supernova-running-shoes | P13: Supernova Rise 3 159,000원 / Ease 99,000~119,000원 / 협업 모델 189,000원 | Q13: 2026-07-01 | R13: FALSE | S13: =IFERROR(VLOOKUP(A13,'02_Recommendation_Attrs'!$A$2:$W$100,23,FALSE),FALSE) -> FALSE | T13: DRAFT | U13: PDB_v0.1 | V13: 데일리/입문 | W13: 입문자부터 일반 러너까지 편안함과 안정감을 중시하는 데일리 러닝화. | X13: EXACT_MSRP_MISSING;CATEGORY_OR_SHARED_URL;DIRECT_IMAGE_URL_NOT_VERIFIED | Y13: 2026-08-28
A14: GM-AD-ADIZERO-SL-2 | B14: adidas | C14: 아디다스 | D14: Adizero | E14: Adizero SL | F14: 2 | G14: adidas Adizero SL 2 | H14: KR | I14: KRW | J14: CURRENT | K14: TRUE | L14: https://www.adidas.co.kr/men-adizero-running | N14: https://www.adidas.co.kr/men-adizero-running | O14: 149000 | P14: Adizero SL 2 149,000원 / EVO SL 209,000원 / Adios Pro 4 299,000원 | Q14: 2026-07-02 | R14: TRUE | S14: =AND(H14="KR",K14=TRUE,O14<>"",IFERROR(VLOOKUP(A14,'02_Recommendation_Attrs'!$A$2:$W$100,23,FALSE),FALSE),IFERROR(VLOOKUP(A14,'05_v0.2_Benchmark'!$A$2:$AC$31,29,FALSE),FALSE)) -> TRUE | T14: VERIFIED | U14: PDB_v0.2 | V14: 템포/레이스 | W14: 경량·반응성·속도 중심. SL 2는 빠른 데일리/훈련, EVO SL은 템포·스피드 훈련, Adios Pro 4는 레이스용으로 적합. | X14: CATEGORY_OR_SHARED_URL;DIRECT_IMAGE_URL_NOT_VERIFIED | Y14: 2026-08-28
A15: GM-AD-ADIZERO-EVO-SL-BASE | B15: adidas | C15: 아디다스 | D15: Adizero | E15: Adizero EVO SL | G15: adidas Adizero EVO SL | H15: KR | I15: KRW | J15: CURRENT | K15: TRUE | L15: https://www.adidas.co.kr/men-adizero-running | N15: https://www.adidas.co.kr/men-adizero-running | O15: 209000 | P15: Adizero SL 2 149,000원 / EVO SL 209,000원 / Adios Pro 4 299,000원 | Q15: 2026-07-02 | R15: TRUE | S15: =AND(H15="KR",K15=TRUE,O15<>"",IFERROR(VLOOKUP(A15,'02_Recommendation_Attrs'!$A$2:$W$100,23,FALSE),FALSE),IFERROR(VLOOKUP(A15,'05_v0.2_Benchmark'!$A$2:$AC$31,29,FALSE),FALSE)) -> TRUE | T15: VERIFIED | U15: PDB_v0.2 | V15: 템포/레이스 | W15: 경량·반응성·속도 중심. SL 2는 빠른 데일리/훈련, EVO SL은 템포·스피드 훈련, Adios Pro 4는 레이스용으로 적합. | X15: CATEGORY_OR_SHARED_URL;DIRECT_IMAGE_URL_NOT_VERIFIED | Y15: 2026-08-28
A16: GM-AD-ADIZERO-ADIOS-PRO-4 | B16: adidas | C16: 아디다스 | D16: Adizero | E16: Adizero Adios Pro | F16: 4 | G16: adidas Adizero Adios Pro 4 | H16: KR | I16: KRW | J16: CURRENT | K16: TRUE | L16: https://www.adidas.co.kr/men-adizero-running | N16: https://www.adidas.co.kr/men-adizero-running | O16: 299000 | P16: Adizero SL 2 149,000원 / EVO SL 209,000원 / Adios Pro 4 299,000원 | Q16: 2026-07-02 | R16: TRUE | S16: =AND(H16="KR",K16=TRUE,O16<>"",IFERROR(VLOOKUP(A16,'02_Recommendation_Attrs'!$A$2:$W$100,23,FALSE),FALSE),IFERROR(VLOOKUP(A16,'05_v0.2_Benchmark'!$A$2:$AC$31,29,FALSE),FALSE)) -> TRUE | T16: VERIFIED | U16: PDB_v0.2 | V16: 템포/레이스 | W16: 경량·반응성·속도 중심. SL 2는 빠른 데일리/훈련, EVO SL은 템포·스피드 훈련, Adios Pro 4는 레이스용으로 적합. | X16: CATEGORY_OR_SHARED_URL;DIRECT_IMAGE_URL_NOT_VERIFIED | Y16: 2026-08-28
A17: GM-AD-DURAMO-SL-2 | B17: adidas | C17: 아디다스 | D17: Duramo | E17: Duramo SL | F17: 2 | G17: adidas Duramo SL 2 | H17: KR | I17: KRW | J17: CURRENT | K17: TRUE | L17: https://www.adidas.co.kr/duramo | N17: https://www.adidas.co.kr/duramo | O17: 79000 | P17: Duramo SL 79,000원 / Duramo Speed 2 99,000원 | Q17: 2026-07-01 | R17: TRUE | S17: =AND(H17="KR",K17=TRUE,O17<>"",IFERROR(VLOOKUP(A17,'02_Recommendation_Attrs'!$A$2:$W$100,23,FALSE),FALSE),IFERROR(VLOOKUP(A17,'05_v0.2_Benchmark'!$A$2:$AC$31,29,FALSE),FALSE)) -> FALSE | T17: DRAFT | U17: PDB_v0.2 | V17: 가성비/입문 | W17: 가성비 입문용. 기본 쿠션, 통기성, 부담 없는 가격대가 강점. | X17: CATEGORY_OR_SHARED_URL;DIRECT_IMAGE_URL_NOT_VERIFIED | Y17: 2026-08-28
A18: GM-AD-DURAMO-SPEED-2 | B18: adidas | C18: 아디다스 | D18: Duramo | E18: Duramo Speed | F18: 2 | G18: adidas Duramo Speed 2 | H18: KR | I18: KRW | J18: CURRENT | K18: TRUE | L18: https://www.adidas.co.kr/duramo | N18: https://www.adidas.co.kr/duramo | O18: 99000 | P18: Duramo SL 79,000원 / Duramo Speed 2 99,000원 | Q18: 2026-07-01 | R18: FALSE | S18: =IFERROR(VLOOKUP(A18,'02_Recommendation_Attrs'!$A$2:$W$100,23,FALSE),FALSE) -> FALSE | T18: DRAFT | U18: PDB_v0.1 | V18: 가성비/입문 | W18: 가성비 입문용. 기본 쿠션, 통기성, 부담 없는 가격대가 강점. | X18: CATEGORY_OR_SHARED_URL;DIRECT_IMAGE_URL_NOT_VERIFIED | Y18: 2026-08-28
A19: GM-NB-FRESH-FOAM-X-1080-V15 | B19: New Balance | C19: 뉴발란스 | D19: 1080 | E19: Fresh Foam X 1080 | F19: v15 | G19: New Balance Fresh Foam X 1080 v15 | H19: KR | I19: KRW | J19: CURRENT | K19: TRUE | L19: https://pay.nbkorea.com/product/productDetail.action?colCode=19&styleCode=NBPFGS102T | N19: https://pay.nbkorea.com/product/productDetail.action?colCode=19&styleCode=NBPFGS102T | O19: 209000 | P19: 209,000원 | Q19: 2026-07-02 | R19: TRUE | S19: =AND(H19="KR",K19=TRUE,O19<>"",IFERROR(VLOOKUP(A19,'02_Recommendation_Attrs'!$A$2:$W$100,23,FALSE),FALSE),IFERROR(VLOOKUP(A19,'05_v0.2_Benchmark'!$A$2:$AC$31,29,FALSE),FALSE)) -> TRUE | T19: VERIFIED | U19: PDB_v0.2 | V19: 쿠션/장거리 | W19: 최상급 쿠셔닝 데일리·장거리용. 부드러운 착화감과 편안한 발구름 중심. | X19: DIRECT_IMAGE_URL_NOT_VERIFIED | Y19: 2026-08-28
A20: GM-NB-FRESH-FOAM-X-880-V15 | B20: New Balance | C20: 뉴발란스 | D20: 880 | E20: Fresh Foam X 880 | F20: v15 | G20: New Balance Fresh Foam X 880 v15 | H20: KR | I20: KRW | J20: CURRENT | K20: TRUE | L20: https://pay.nbkorea.com/product/productDetail.action?colCode=19&styleCode=NBPFGS107T | N20: https://pay.nbkorea.com/product/productDetail.action?colCode=19&styleCode=NBPFGS107T | O20: 189000 | P20: 189,000원 | Q20: 2026-07-02 | R20: TRUE | S20: =AND(H20="KR",K20=TRUE,O20<>"",IFERROR(VLOOKUP(A20,'02_Recommendation_Attrs'!$A$2:$W$100,23,FALSE),FALSE),IFERROR(VLOOKUP(A20,'05_v0.2_Benchmark'!$A$2:$AC$31,29,FALSE),FALSE)) -> TRUE | T20: VERIFIED | U20: PDB_v0.2 | V20: 데일리/중립 | W20: 중립 데일리 트레이너. 1080보다 조금 더 밀도 있고 안정적인 쿠션을 선호하는 러너에게 적합. | X20: DIRECT_IMAGE_URL_NOT_VERIFIED | Y20: 2026-08-28
A21: GM-NB-FRESH-FOAM-X-860-V15 | B21: New Balance | C21: 뉴발란스 | D21: 860 | E21: Fresh Foam X 860 | F21: v15 | G21: New Balance Fresh Foam X 860 v15 | H21: KR | I21: KRW | J21: CURRENT | K21: TRUE | L21: https://pay.nbkorea.com/product/productDetail.action?colCode=19&styleCode=NBPFGS109K | N21: https://pay.nbkorea.com/product/productDetail.action?colCode=19&styleCode=NBPFGS109K | O21: 189000 | P21: 189,000원 | Q21: 2026-07-02 | R21: TRUE | S21: =AND(H21="KR",K21=TRUE,O21<>"",IFERROR(VLOOKUP(A21,'02_Recommendation_Attrs'!$A$2:$W$100,23,FALSE),FALSE),IFERROR(VLOOKUP(A21,'05_v0.2_Benchmark'!$A$2:$AC$31,29,FALSE),FALSE)) -> TRUE | T21: VERIFIED | U21: PDB_v0.2 | V21: 안정화 | W21: 안정화 러닝화. 과내전 보정과 지지감이 필요한 러너에게 적합. | X21: DIRECT_IMAGE_URL_NOT_VERIFIED | Y21: 2026-08-28
A22: GM-NB-FUELCELL-SUPERCOMP-ELITE-V5 | B22: New Balance | C22: 뉴발란스 | D22: SC Elite | E22: FuelCell SuperComp Elite | F22: v5 | G22: New Balance FuelCell SuperComp Elite v5 | H22: KR | I22: KRW | J22: CURRENT | K22: TRUE | L22: https://www.lotteimall.com/goods/viewGoodsDetail.lotte?goods_no=3083436989&gad_source=1&gad_campaignid=16158532513&gclid=EAIaIQobChMIrJHZ8ey_lQMVwtYWBR2JrTF9EAYYASABEgLORvD_BwE&gbraid=0AAAAADuYO-SDPnQA8IA9eUOL6kptFEVYT&chl_dtl_no=&chl_no=169230 | N22: https://www.lotteimall.com/goods/viewGoodsDetail.lotte?goods_no=3083436989&gad_source=1&gad_campaignid=16158532513&gclid=EAIaIQobChMIrJHZ8ey_lQMVwtYWBR2JrTF9EAYYASABEgLORvD_BwE&gbraid=0AAAAADuYO-SDPnQA8IA9eUOL6kptFEVYT&chl_dtl_no=&chl_no=169230 | O22: 349000 | P22: 349,000원 | Q22: 2026-07-02 | R22: TRUE | S22: =AND(H22="KR",K22=TRUE,O22<>"",IFERROR(VLOOKUP(A22,'02_Recommendation_Attrs'!$A$2:$W$100,23,FALSE),FALSE),IFERROR(VLOOKUP(A22,'05_v0.2_Benchmark'!$A$2:$AC$31,29,FALSE),FALSE)) -> TRUE | T22: VERIFIED | U22: PDB_v0.2 | V22: 레이스/카본 | W22: 카본 레이싱화. 10km~마라톤 PB 도전, 기록 단축 목적의 상급 러너에게 적합. | X22: DIRECT_IMAGE_URL_NOT_VERIFIED | Y22: 2026-08-28
A23: GM-HK-CLIFTON-10 | B23: HOKA | C23: 호카 | D23: Clifton | E23: Clifton | F23: 10 | G23: HOKA Clifton 10 | H23: US | I23: USD | J23: CURRENT | K23: FALSE | L23: https://www.hoka.com/en/us/mens-road/ | N23: https://www.hoka.com/en/us/mens-road/ | O23: 155 | P23: $155 전후 | Q23: 2026-07-02 | R23: FALSE | S23: =IFERROR(VLOOKUP(A23,'02_Recommendation_Attrs'!$A$2:$W$100,23,FALSE),FALSE) -> FALSE | T23: DRAFT | U23: PDB_v0.1 | V23: 데일리/올라운드 | W23: 데일리 올라운드. 가볍고 부드러운 쿠셔닝, 조깅·이지런·걷기 겸용에 적합. | X23: KR_SALE_NOT_CONFIRMED_IN_SOURCE;CATEGORY_OR_SHARED_URL;DIRECT_IMAGE_URL_NOT_VERIFIED | Y23: 2026-08-28
A24: GM-HK-BONDI-9 | B24: HOKA | C24: 호카 | D24: Bondi | E24: Bondi | F24: 9 | G24: HOKA Bondi 9 | H24: US | I24: USD | J24: CURRENT | K24: FALSE | L24: https://www.hoka.com/en/us/mens-road/ | N24: https://www.hoka.com/en/us/mens-road/ | O24: 175 | P24: $175 전후 | Q24: 2026-07-02 | R24: FALSE | S24: =IFERROR(VLOOKUP(A24,'02_Recommendation_Attrs'!$A$2:$W$100,23,FALSE),FALSE) -> FALSE | T24: DRAFT | U24: PDB_v0.1 | V24: 맥스쿠션/워킹 | W24: 맥시 쿠셔닝 중심. 충격 흡수와 편안함을 크게 중시하는 러너·워킹 사용자에게 적합. | X24: KR_SALE_NOT_CONFIRMED_IN_SOURCE;CATEGORY_OR_SHARED_URL;DIRECT_IMAGE_URL_NOT_VERIFIED | Y24: 2026-08-28
A25: GM-HK-ARAHI-8 | B25: HOKA | C25: 호카 | D25: Arahi | E25: Arahi | F25: 8 | G25: HOKA Arahi 8 | H25: US | I25: USD | J25: CURRENT | K25: FALSE | L25: https://www.hoka.com/en/us/mens-road/ | N25: https://www.hoka.com/en/us/mens-road/ | O25: 150 | P25: $150 전후 | Q25: 2026-07-02 | R25: FALSE | S25: =IFERROR(VLOOKUP(A25,'02_Recommendation_Attrs'!$A$2:$W$100,23,FALSE),FALSE) -> FALSE | T25: DRAFT | U25: PDB_v0.1 | V25: 안정화 | W25: 안정화 러닝화. 과내전 보정과 안정성을 원하되 쿠션감도 원하는 러너에게 적합. | X25: KR_SALE_NOT_CONFIRMED_IN_SOURCE;CATEGORY_OR_SHARED_URL;DIRECT_IMAGE_URL_NOT_VERIFIED | Y25: 2026-08-28
A26: GM-HK-MACH-7 | B26: HOKA | C26: 호카 | D26: Mach | E26: Mach | F26: 7 | G26: HOKA Mach 7 | H26: US | I26: USD | J26: CURRENT | K26: FALSE | L26: https://www.hoka.com/en/us/mens-road/ | N26: https://www.hoka.com/en/us/mens-road/ | O26: 145 | P26: $145 전후 | Q26: 2026-07-02 | R26: FALSE | S26: =IFERROR(VLOOKUP(A26,'02_Recommendation_Attrs'!$A$2:$W$100,23,FALSE),FALSE) -> FALSE | T26: DRAFT | U26: PDB_v0.1 | V26: 템포/스피드훈련 | W26: 템포·스피드 훈련용. 반응성과 가벼운 추진감이 강점인 빠른 데일리 트레이너. | X26: KR_SALE_NOT_CONFIRMED_IN_SOURCE;CATEGORY_OR_SHARED_URL;DIRECT_IMAGE_URL_NOT_VERIFIED | Y26: 2026-08-28
A27: GM-HK-CIELO-X1-3_0 | B27: HOKA | C27: 호카 | D27: Cielo X1 | E27: Cielo X1 | F27: 3.0 | G27: HOKA Cielo X1 3.0 | H27: US | I27: USD | J27: CURRENT | K27: FALSE | L27: https://www.hoka.com/en/us/mens-road/ | N27: https://www.hoka.com/en/us/mens-road/ | O27: 275 | P27: $275 전후 | Q27: 2026-07-02 | R27: FALSE | S27: =IFERROR(VLOOKUP(A27,'02_Recommendation_Attrs'!$A$2:$W$100,23,FALSE),FALSE) -> FALSE | T27: DRAFT | U27: PDB_v0.1 | V27: 레이스/카본 | W27: 레이스용 고성능 카본 라인. 강한 반발력과 속도 지향, 대회·기록 목적에 적합. | X27: KR_SALE_NOT_CONFIRMED_IN_SOURCE;CATEGORY_OR_SHARED_URL;DIRECT_IMAGE_URL_NOT_VERIFIED | Y27: 2026-08-28
A28: GM-AS-GEL-KAYANO-33 | B28: ASICS | C28: 아식스 | D28: GEL-KAYANO | E28: GEL-KAYANO | F28: 33 | G28: ASICS GEL-KAYANO 33 | H28: KR | I28: KRW | J28: CURRENT | K28: TRUE | L28: https://www.asics.co.kr/c/m-running-shoes | N28: https://www.asics.co.kr/c/m-running-shoes | O28: 199000 | P28: 199,000원 | Q28: 2026-07-02 | R28: TRUE | S28: =AND(H28="KR",K28=TRUE,O28<>"",IFERROR(VLOOKUP(A28,'02_Recommendation_Attrs'!$A$2:$W$100,23,FALSE),FALSE),IFERROR(VLOOKUP(A28,'05_v0.2_Benchmark'!$A$2:$AC$31,29,FALSE),FALSE)) -> TRUE | T28: VERIFIED | U28: PDB_v0.2 | V28: 안정화 | W28: 안정화 대표 모델. 지지력과 안정성을 중시하는 러너, 장거리에서 발 흔들림을 줄이고 싶은 러너에게 적합. | X28: CATEGORY_OR_SHARED_URL;DIRECT_IMAGE_URL_NOT_VERIFIED | Y28: 2026-08-28
A29: GM-AS-GEL-KAYANO-32 | B29: ASICS | C29: 아식스 | D29: GEL-KAYANO | E29: GEL-KAYANO | F29: 32 | G29: ASICS GEL-KAYANO 32 | H29: KR | I29: KRW | J29: UNKNOWN | K29: TRUE | L29: https://www.asics.co.kr/c/m-running-shoes | N29: https://www.asics.co.kr/c/m-running-shoes | O29: 199000 | P29: 199,000원 | Q29: 2026-07-02 | R29: FALSE | S29: =IFERROR(VLOOKUP(A29,'02_Recommendation_Attrs'!$A$2:$W$100,23,FALSE),FALSE) -> FALSE | T29: DRAFT | U29: PDB_v0.1 | V29: 안정화 | W29: 안정화 대표 모델. 지지력과 안정성을 중시하는 러너, 장거리에서 발 흔들림을 줄이고 싶은 러너에게 적합. | X29: CATEGORY_OR_SHARED_URL;DIRECT_IMAGE_URL_NOT_VERIFIED | Y29: 2026-08-28
A30: GM-AS-GEL-NIMBUS-28 | B30: ASICS | C30: 아식스 | D30: GEL-NIMBUS | E30: GEL-NIMBUS | F30: 28 | G30: ASICS GEL-NIMBUS 28 | H30: KR | I30: KRW | J30: CURRENT | K30: TRUE | L30: https://www.asics.co.kr/c/m-running-shoes | N30: https://www.asics.co.kr/c/m-running-shoes | O30: 199000 | P30: 199,000원 | Q30: 2026-07-02 | R30: TRUE | S30: =AND(H30="KR",K30=TRUE,O30<>"",IFERROR(VLOOKUP(A30,'02_Recommendation_Attrs'!$A$2:$W$100,23,FALSE),FALSE),IFERROR(VLOOKUP(A30,'05_v0.2_Benchmark'!$A$2:$AC$31,29,FALSE),FALSE)) -> TRUE | T30: VERIFIED | U30: PDB_v0.2 | V30: 쿠션/장거리 | W30: 맥스 쿠션화. 부드러운 착지감과 편안함 중심, 장거리·데일리 러닝에 적합. | X30: CATEGORY_OR_SHARED_URL;DIRECT_IMAGE_URL_NOT_VERIFIED | Y30: 2026-08-28
A31: GM-AS-NOVABLAST-5 | B31: ASICS | C31: 아식스 | D31: NOVABLAST | E31: NOVABLAST | F31: 5 | G31: ASICS NOVABLAST 5 | H31: KR | I31: KRW | J31: CURRENT | K31: TRUE | L31: https://www.asics.co.kr/c/m-running-shoes | N31: https://www.asics.co.kr/c/m-running-shoes | O31: 169000 | P31: 169,000원부터 | Q31: 2026-07-02 | R31: TRUE | S31: =AND(H31="KR",K31=TRUE,O31<>"",IFERROR(VLOOKUP(A31,'02_Recommendation_Attrs'!$A$2:$W$100,23,FALSE),FALSE),IFERROR(VLOOKUP(A31,'05_v0.2_Benchmark'!$A$2:$AC$31,29,FALSE),FALSE)) -> TRUE | T31: VERIFIED | U31: PDB_v0.2 | V31: 데일리/반발 | W31: 반발감이 좋은 바운싱 계열. 데일리 러닝에 재미있는 러닝감을 더하고 싶은 중립 러너에게 적합. | X31: CATEGORY_OR_SHARED_URL;DIRECT_IMAGE_URL_NOT_VERIFIED | Y31: 2026-08-28
A32: GM-AS-SUPERBLAST-2 | B32: ASICS | C32: 아식스 | D32: SUPERBLAST | E32: SUPERBLAST | F32: 2 | G32: ASICS SUPERBLAST 2 | H32: KR | I32: KRW | J32: UNKNOWN | K32: TRUE | L32: https://www.asics.co.kr/c/m-running-shoes | N32: https://www.asics.co.kr/c/m-running-shoes | O32: 249000 | P32: SUPERBLAST 2 249,000원 / SUPERBLAST 3 259,000원 | Q32: 2026-07-02 | R32: FALSE | S32: =IFERROR(VLOOKUP(A32,'02_Recommendation_Attrs'!$A$2:$W$100,23,FALSE),FALSE) -> FALSE | T32: DRAFT | U32: PDB_v0.1 | V32: 슈퍼트레이너 | W32: 무카본 슈퍼트레이너 성격. 장거리 훈련, 템포, 다목적 활용에 강함. | X32: CATEGORY_OR_SHARED_URL;DIRECT_IMAGE_URL_NOT_VERIFIED | Y32: 2026-08-28
A33: GM-AS-SUPERBLAST-3 | B33: ASICS | C33: 아식스 | D33: SUPERBLAST | E33: SUPERBLAST | F33: 3 | G33: ASICS SUPERBLAST 3 | H33: KR | I33: KRW | J33: CURRENT | K33: TRUE | L33: https://www.asics.co.kr/c/m-running-shoes | N33: https://www.asics.co.kr/c/m-running-shoes | O33: 259000 | P33: SUPERBLAST 2 249,000원 / SUPERBLAST 3 259,000원 | Q33: 2026-07-02 | R33: TRUE | S33: =AND(H33="KR",K33=TRUE,O33<>"",IFERROR(VLOOKUP(A33,'02_Recommendation_Attrs'!$A$2:$W$100,23,FALSE),FALSE),IFERROR(VLOOKUP(A33,'05_v0.2_Benchmark'!$A$2:$AC$31,29,FALSE),FALSE)) -> TRUE | T33: VERIFIED | U33: PDB_v0.2 | V33: 슈퍼트레이너 | W33: 무카본 슈퍼트레이너 성격. 장거리 훈련, 템포, 다목적 활용에 강함. | X33: CATEGORY_OR_SHARED_URL;DIRECT_IMAGE_URL_NOT_VERIFIED | Y33: 2026-08-28
A34: GM-AS-METASPEED-SKY-TOKYO | B34: ASICS | C34: 아식스 | D34: METASPEED | E34: METASPEED SKY | F34: TOKYO | G34: ASICS METASPEED SKY TOKYO | H34: KR | I34: KRW | J34: CURRENT | K34: TRUE | L34: https://www.asics.co.kr/c/m-running-shoes | N34: https://www.asics.co.kr/c/m-running-shoes | O34: 329000 | P34: 329,000원 | Q34: 2026-07-02 | R34: TRUE | S34: =AND(H34="KR",K34=TRUE,O34<>"",IFERROR(VLOOKUP(A34,'02_Recommendation_Attrs'!$A$2:$W$100,23,FALSE),FALSE),IFERROR(VLOOKUP(A34,'05_v0.2_Benchmark'!$A$2:$AC$31,29,FALSE),FALSE)) -> TRUE | T34: VERIFIED | U34: PDB_v0.2 | V34: 레이스/카본 | W34: 레이스용 카본 계열. 기록 단축과 추진력 중심, 상급자 대회용에 적합. | X34: CATEGORY_OR_SHARED_URL;DIRECT_IMAGE_URL_NOT_VERIFIED | Y34: 2026-08-28
A35: GM-AS-METASPEED-EDGE-TOKYO | B35: ASICS | C35: 아식스 | D35: METASPEED | E35: METASPEED EDGE | F35: TOKYO | G35: ASICS METASPEED EDGE TOKYO | H35: KR | I35: KRW | J35: CURRENT | K35: TRUE | L35: https://www.asics.co.kr/c/m-running-shoes | N35: https://www.asics.co.kr/c/m-running-shoes | O35: 329000 | P35: 329,000원 | Q35: 2026-07-02 | R35: FALSE | S35: =IFERROR(VLOOKUP(A35,'02_Recommendation_Attrs'!$A$2:$W$100,23,FALSE),FALSE) -> FALSE | T35: DRAFT | U35: PDB_v0.1 | V35: 레이스/카본 | W35: 레이스용 카본 계열. 기록 단축과 추진력 중심, 상급자 대회용에 적합. | X35: CATEGORY_OR_SHARED_URL;DIRECT_IMAGE_URL_NOT_VERIFIED | Y35: 2026-08-28
A36: GM-AS-MAGIC-SPEED-5 | B36: ASICS | C36: 아식스 | D36: Magic Speed | E36: Magic Speed | F36: 5 | G36: ASICS Magic Speed 5 | H36: KR | I36: KRW | J36: CURRENT | K36: TRUE | L36: https://www.asics.co.kr/c/m-running-shoes | N36: https://www.asics.co.kr/c/m-running-shoes | O36: 209000 | P36: Magic Speed 4 199,000원 / Magic Speed 5 209,000원 | Q36: 2026-07-02 | R36: TRUE | S36: =AND(H36="KR",K36=TRUE,O36<>"",IFERROR(VLOOKUP(A36,'02_Recommendation_Attrs'!$A$2:$W$100,23,FALSE),FALSE),IFERROR(VLOOKUP(A36,'05_v0.2_Benchmark'!$A$2:$AC$31,29,FALSE),FALSE)) -> TRUE | T36: VERIFIED | U36: PDB_v0.2 | V36: 템포/스피드훈련 | W36: 가성비 카본·템포 성격. 레이스 입문과 스피드 훈련에 적합. | X36: CATEGORY_OR_SHARED_URL;DIRECT_IMAGE_URL_NOT_VERIFIED | Y36: 2026-08-28
A37: GM-AS-MAGIC-SPEED-4 | B37: ASICS | C37: 아식스 | D37: Magic Speed | E37: Magic Speed | F37: 4 | G37: ASICS Magic Speed 4 | H37: KR | I37: KRW | J37: UNKNOWN | K37: TRUE | L37: https://www.asics.co.kr/c/m-running-shoes | N37: https://www.asics.co.kr/c/m-running-shoes | O37: 199000 | P37: Magic Speed 4 199,000원 / Magic Speed 5 209,000원 | Q37: 2026-07-02 | R37: FALSE | S37: =IFERROR(VLOOKUP(A37,'02_Recommendation_Attrs'!$A$2:$W$100,23,FALSE),FALSE) -> FALSE | T37: DRAFT | U37: PDB_v0.1 | V37: 템포/스피드훈련 | W37: 가성비 카본·템포 성격. 레이스 입문과 스피드 훈련에 적합. | X37: CATEGORY_OR_SHARED_URL;DIRECT_IMAGE_URL_NOT_VERIFIED | Y37: 2026-08-28
A38: GM-SC-RIDE-19 | B38: Saucony | C38: 써코니 | D38: Ride | E38: Ride | F38: 19 | G38: Saucony Ride 19 | H38: KR | I38: KRW | J38: CURRENT | K38: TRUE | L38: https://saucony.co.kr/category/%EB%9D%BC%EC%9D%B4%EB%93%9C/114 | N38: https://saucony.co.kr/category/%EB%9D%BC%EC%9D%B4%EB%93%9C/114 | O38: 179000 | P38: 179,000원 | Q38: 2026-07-02 | R38: TRUE | S38: =AND(H38="KR",K38=TRUE,O38<>"",IFERROR(VLOOKUP(A38,'02_Recommendation_Attrs'!$A$2:$W$100,23,FALSE),FALSE),IFERROR(VLOOKUP(A38,'05_v0.2_Benchmark'!$A$2:$AC$31,29,FALSE),FALSE)) -> TRUE | T38: VERIFIED | U38: PDB_v0.2 | V38: 데일리/올라운드 | W38: 중립형 데일리 올라운드. 입문~중급 러너의 조깅, 기본 훈련, 일상적인 러닝에 적합. | X38: DIRECT_IMAGE_URL_NOT_VERIFIED | Y38: 2026-08-28
A39: GM-SC-TRIUMPH-23 | B39: Saucony | C39: 써코니 | D39: Triumph | E39: Triumph | F39: 23 | G39: Saucony Triumph 23 | H39: KR | I39: KRW | J39: CURRENT | K39: TRUE | L39: https://saucony.co.kr/product/%EC%97%AC%EC%84%B1-%ED%8A%B8%EB%9D%BC%EC%9D%B4%EC%97%84%ED%94%84-23-%EC%99%80%EC%9D%B4%EB%93%9C-vaporarctic/197/category/42/display/1/ | N39: https://saucony.co.kr/product/%EC%97%AC%EC%84%B1-%ED%8A%B8%EB%9D%BC%EC%9D%B4%EC%97%84%ED%94%84-23-%EC%99%80%EC%9D%B4%EB%93%9C-vaporarctic/197/category/42/display/1/ | O39: 199000 | P39: 199,000원 | Q39: 2026-07-02 | R39: TRUE | S39: =AND(H39="KR",K39=TRUE,O39<>"",IFERROR(VLOOKUP(A39,'02_Recommendation_Attrs'!$A$2:$W$100,23,FALSE),FALSE),IFERROR(VLOOKUP(A39,'05_v0.2_Benchmark'!$A$2:$AC$31,29,FALSE),FALSE)) -> TRUE | T39: VERIFIED | U39: PDB_v0.2 | V39: 쿠션/장거리 | W39: 프리미엄 쿠셔닝 중심. 장거리 러닝, 회복주, 부드러운 착지감을 원하는 러너에게 적합. | X39: DIRECT_IMAGE_URL_NOT_VERIFIED | Y39: 2026-08-28
A40: GM-SC-GUIDE-19 | B40: Saucony | C40: 써코니 | D40: Guide | E40: Guide | F40: 19 | G40: Saucony Guide 19 | H40: KR | I40: KRW | J40: CURRENT | K40: TRUE | L40: https://saucony.co.kr/product/list.html?cate_no=131 | N40: https://saucony.co.kr/product/list.html?cate_no=131 | O40: 179000 | P40: 179,000원 | Q40: 2026-07-02 | R40: TRUE | S40: =AND(H40="KR",K40=TRUE,O40<>"",IFERROR(VLOOKUP(A40,'02_Recommendation_Attrs'!$A$2:$W$100,23,FALSE),FALSE),IFERROR(VLOOKUP(A40,'05_v0.2_Benchmark'!$A$2:$AC$31,29,FALSE),FALSE)) -> TRUE | T40: VERIFIED | U40: PDB_v0.2 | V40: 안정화 | W40: 발의 흔들림을 줄이고 안정적인 착지를 돕는 라인. 과내전 성향이나 안정감을 원하는 러너에게 적합. | X40: DIRECT_IMAGE_URL_NOT_VERIFIED | Y40: 2026-08-28
...

Sheet 02_Recommendation_Attrs
A1: product_id | B1: display_name | C1: primary_use | D1: secondary_use_tags | E1: cushion_score | F1: stability_score | G1: responsiveness_score | H1: weight_g | I1: drop_mm | J1: plate_type | K1: fit_width | L1: wide_option | M1: runner_level_fit | N1: distance_fit | O1: caution_tags | P1: caution_detail_tags | Q1: review_evidence_count | R1: evidence_source_summary | S1: normalization_rule_version | T1: data_status | U1: missing_required_count | V1: eligibility_gap_summary | W1: ready_for_recommendation
A2: GM-NK-PEGASUS-42 | B2: Nike Pegasus 42 | C2: DAILY | E2: ='05_v0.2_Benchmark'!O21 -> 3 | F2: ='05_v0.2_Benchmark'!P21 -> 4 | G2: ='05_v0.2_Benchmark'!Q21 -> 3 | H2: ='05_v0.2_Benchmark'!R21 -> 282.6 | I2: ='05_v0.2_Benchmark'!S21 -> 10.7 | J2: ='05_v0.2_Benchmark'!T21 -> NONE | K2: ='05_v0.2_Benchmark'!U21 -> STANDARD | L2: ='05_v0.2_Benchmark'!V21 -> TRUE | ... N2: ='05_v0.2_Benchmark'!X21 -> ALL | O2: HEAVY;OTHER | P2: FOREFOOT_PRESSURE;HEAT_BREATHABILITY | Q2: 7 | R2: A_RTINGS | RTINGS_DIRECT | 공식/기존 Review Evidence 병행 | S2: PERF_NORM_v0.2 / USE_CASE_v0.2 / FIT_v0.2 | T2: VERIFIED | U2: =COUNTBLANK(E2:I2)+IF(J2="UNKNOWN",1,0)+IF(K2="UNKNOWN",1,0)+IF(L2="UNKNOWN",1,0)+IF(M2="UNKNOWN",1,0)+IF(N2="UNKNOWN",1,0) -> 0 | V2: =IF(U2=0,"",_xludf.TEXTJOIN(", ",TRUE,IF(E2="","cushion_score",""),IF(F2="","stability_score",""),IF(G2="","responsiveness_score",""),IF(H2="","weight_g",""),IF(I2="","drop_mm",""),IF(J2="UNKNOWN","plate_type",""),IF(K2="UNKNOWN","fit_width",""),IF(L2="UNKNOWN","wide_option",""),IF(M2="UNKNOWN","runner_level_fit",""),IF(N2="UNKNOWN","distance_fit",""))) | W2: =AND(U2=0,T2="VERIFIED") -> TRUE
A3: GM-NK-VOMERO-18 | B3: Nike Vomero 18 | C3: LONG | D3: DAILY | E3: ='05_v0.2_Benchmark'!O11 -> 4 | F3: ='05_v0.2_Benchmark'!P11 -> 5 | G3: ='05_v0.2_Benchmark'!Q11 -> 3 | H3: ='05_v0.2_Benchmark'!R11 -> 297.5 | I3: ='05_v0.2_Benchmark'!S11 -> 10.3 | J3: ='05_v0.2_Benchmark'!T11 -> NONE | K3: ='05_v0.2_Benchmark'!U11 -> NARROW | L3: ='05_v0.2_Benchmark'!V11 -> TRUE | ... N3: ='05_v0.2_Benchmark'!X11 -> LONG | O3: FIT_NARROW;OTHER | P3: HEAT_BREATHABILITY | Q3: 5 | R3: A_RTINGS | RTINGS_DIRECT | 공식/기존 Review Evidence 병행 | S3: PERF_NORM_v0.2 / USE_CASE_v0.2 / FIT_v0.2 | T3: VERIFIED | U3: =COUNTBLANK(E3:I3)+IF(J3="UNKNOWN",1,0)+IF(K3="UNKNOWN",1,0)+IF(L3="UNKNOWN",1,0)+IF(M3="UNKNOWN",1,0)+IF(N3="UNKNOWN",1,0) -> 0 | V3: =IF(U3=0,"",_xludf.TEXTJOIN(", ",TRUE,IF(E3="","cushion_score",""),IF(F3="","stability_score",""),IF(G3="","responsiveness_score",""),IF(H3="","weight_g",""),IF(I3="","drop_mm",""),IF(J3="UNKNOWN","plate_type",""),IF(K3="UNKNOWN","fit_width",""),IF(L3="UNKNOWN","wide_option",""),IF(M3="UNKNOWN","runner_level_fit",""),IF(N3="UNKNOWN","distance_fit",""))) | W3: =AND(U3=0,T3="VERIFIED") -> TRUE
A4: GM-NK-VOMERO-PLUS-BASE | B4: Nike Vomero Plus | C4: LONG | D4: DAILY | J4: UNKNOWN | K4: UNKNOWN | L4: UNKNOWN | M4: UNKNOWN | N4: LONG | Q4: 0 | R4: Official migrated + external review 0건 | S4: USE_CASE_MIGRATION_v0.1 / FIT_CAUTION_RULE_v0.1 | T4: DRAFT | U4: =COUNTBLANK(E4:I4)+IF(J4="UNKNOWN",1,0)+IF(K4="UNKNOWN",1,0)+IF(L4="UNKNOWN",1,0)+IF(M4="UNKNOWN",1,0)+IF(N4="UNKNOWN",1,0) -> 9 | V4: cushion_score, stability_score, responsiveness_score, weight_g, drop_mm, plate_type, fit_width, wide_option, runner_level_fit | W4: =AND(U4=0,T4="VERIFIED") -> FALSE
A5: GM-NK-VOMERO-PREMIUM-BASE | B5: Nike Vomero Premium | C5: LONG | D5: DAILY | J5: UNKNOWN | K5: UNKNOWN | L5: UNKNOWN | M5: UNKNOWN | N5: LONG | O5: OTHER | Q5: 1 | R5: Official migrated + external review 1건 | S5: USE_CASE_MIGRATION_v0.1 / FIT_CAUTION_RULE_v0.1 | T5: DRAFT | U5: =COUNTBLANK(E5:I5)+IF(J5="UNKNOWN",1,0)+IF(K5="UNKNOWN",1,0)+IF(L5="UNKNOWN",1,0)+IF(M5="UNKNOWN",1,0)+IF(N5="UNKNOWN",1,0) -> 9 | V5: cushion_score, stability_score, responsiveness_score, weight_g, drop_mm, plate_type, fit_width, wide_option, runner_level_fit | W5: =AND(U5=0,T5="VERIFIED") -> FALSE
A6: GM-NK-STRUCTURE-26 | B6: Nike Structure 26 | C6: STABILITY | D6: DAILY | E6: ='05_v0.2_Benchmark'!O17 -> 3 | F6: ='05_v0.2_Benchmark'!P17 -> 5 | G6: ='05_v0.2_Benchmark'!Q17 -> 3 | H6: ='05_v0.2_Benchmark'!R17 -> 296 | I6: ='05_v0.2_Benchmark'!S17 -> 10.1 | J6: ='05_v0.2_Benchmark'!T17 -> NONE | K6: ='05_v0.2_Benchmark'!U17 -> STANDARD | L6: ='05_v0.2_Benchmark'!V17 -> TRUE | ... N6: ='05_v0.2_Benchmark'!X17 -> ALL | O6: HEAVY;OTHER | P6: DURABILITY;HEAT_BREATHABILITY | Q6: 5 | R6: B_RUNREPEAT | RUNREPEAT_RELATIVE | 공식/기존 Review Evidence 병행 | S6: PERF_NORM_v0.2 / USE_CASE_v0.2 / FIT_v0.2 | T6: VERIFIED | U6: =COUNTBLANK(E6:I6)+IF(J6="UNKNOWN",1,0)+IF(K6="UNKNOWN",1,0)+IF(L6="UNKNOWN",1,0)+IF(M6="UNKNOWN",1,0)+IF(N6="UNKNOWN",1,0) -> 0 | V6: =IF(U6=0,"",_xludf.TEXTJOIN(", ",TRUE,IF(E6="","cushion_score",""),IF(F6="","stability_score",""),IF(G6="","responsiveness_score",""),IF(H6="","weight_g",""),IF(I6="","drop_mm",""),IF(J6="UNKNOWN","plate_type",""),IF(K6="UNKNOWN","fit_width",""),IF(L6="UNKNOWN","wide_option",""),IF(M6="UNKNOWN","runner_level_fit",""),IF(N6="UNKNOWN","distance_fit",""))) | W6: =AND(U6=0,T6="VERIFIED") -> TRUE
A7: GM-NK-STRUCTURE-PLUS-BASE | B7: Nike Structure Plus | C7: STABILITY | D7: DAILY | J7: UNKNOWN | K7: UNKNOWN | L7: UNKNOWN | M7: UNKNOWN | N7: UNKNOWN | Q7: 0 | R7: Official migrated + external review 0건 | S7: USE_CASE_MIGRATION_v0.1 / FIT_CAUTION_RULE_v0.1 | T7: DRAFT | U7: =COUNTBLANK(E7:I7)+IF(J7="UNKNOWN",1,0)+IF(K7="UNKNOWN",1,0)+IF(L7="UNKNOWN",1,0)+IF(M7="UNKNOWN",1,0)+IF(N7="UNKNOWN",1,0) -> 10 | V7: cushion_score, stability_score, responsiveness_score, weight_g, drop_mm, plate_type, fit_width, wide_option, runner_level_fit, distance_fit, msrp_krw | W7: =AND(U7=0,T7="VERIFIED") -> FALSE
A8: GM-NK-ZOOM-FLY-6 | B8: Nike Zoom Fly 6 | C8: TEMPO | J8: CARBON | K8: UNKNOWN | L8: UNKNOWN | M8: UNKNOWN | N8: UNKNOWN | O8: AGGRESSIVE_RIDE;OTHER;PLATE_STIFF | P8: FOREFOOT_PRESSURE;HEAT_BREATHABILITY | Q8: 4 | R8: Official migrated + external review 4건 | S8: USE_CASE_MIGRATION_v0.1 / FIT_CAUTION_RULE_v0.1 | T8: DRAFT | U8: =COUNTBLANK(E8:I8)+IF(J8="UNKNOWN",1,0)+IF(K8="UNKNOWN",1,0)+IF(L8="UNKNOWN",1,0)+IF(M8="UNKNOWN",1,0)+IF(N8="UNKNOWN",1,0) -> 9 | V8: cushion_score, stability_score, responsiveness_score, weight_g, drop_mm, fit_width, wide_option, runner_level_fit, distance_fit | W8: =AND(U8=0,T8="VERIFIED") -> FALSE
A9: GM-NK-ALPHAFLY-3 | B9: Nike Alphafly 3 | C9: RACE | J9: CARBON | K9: UNKNOWN | L9: UNKNOWN | M9: ADVANCED | N9: LONG | O9: AGGRESSIVE_RIDE;OTHER | P9: DURABILITY;HEAT_BREATHABILITY | Q9: 2 | R9: Official migrated + external review 2건 | S9: USE_CASE_MIGRATION_v0.1 / FIT_CAUTION_RULE_v0.1 | T9: DRAFT | U9: =COUNTBLANK(E9:I9)+IF(J9="UNKNOWN",1,0)+IF(K9="UNKNOWN",1,0)+IF(L9="UNKNOWN",1,0)+IF(M9="UNKNOWN",1,0)+IF(N9="UNKNOWN",1,0) -> 7 | V9: cushion_score, stability_score, responsiveness_score, weight_g, drop_mm, fit_width, wide_option | W9: =AND(U9=0,T9="VERIFIED") -> FALSE
A10: GM-AD-ULTRABOOST-5X | B10: adidas Ultraboost 5X | C10: LONG | D10: RECOVERY | J10: UNKNOWN | K10: NARROW | L10: UNKNOWN | M10: UNKNOWN | N10: LONG | O10: FIT_NARROW;HEAVY;OTHER | P10: BLISTER | Q10: 5 | R10: Official migrated + external review 5건 | S10: USE_CASE_MIGRATION_v0.1 / FIT_CAUTION_RULE_v0.1 | T10: DRAFT | U10: =COUNTBLANK(E10:I10)+IF(J10="UNKNOWN",1,0)+IF(K10="UNKNOWN",1,0)+IF(L10="UNKNOWN",1,0)+IF(M10="UNKNOWN",1,0)+IF(N10="UNKNOWN",1,0) -> 8 | V10: cushion_score, stability_score, responsiveness_score, weight_g, drop_mm, plate_type, wide_option, runner_level_fit, msrp_krw | W10: =AND(U10=0,T10="VERIFIED") -> FALSE
A11: GM-AD-ULTRABOOST-1-0-ATR-BASE | B11: adidas Ultraboost 1.0 ATR | C11: LONG | D11: RECOVERY | J11: UNKNOWN | K11: UNKNOWN | L11: UNKNOWN | M11: UNKNOWN | N11: LONG | Q11: 0 | R11: Official migrated + external review 0건 | S11: USE_CASE_MIGRATION_v0.1 / FIT_CAUTION_RULE_v0.1 | T11: DRAFT | U11: =COUNTBLANK(E11:I11)+IF(J11="UNKNOWN",1,0)+IF(K11="UNKNOWN",1,0)+IF(L11="UNKNOWN",1,0)+IF(M11="UNKNOWN",1,0)+IF(N11="UNKNOWN",1,0) -> 9 | V11: cushion_score, stability_score, responsiveness_score, weight_g, drop_mm, plate_type, fit_width, wide_option, runner_level_fit, msrp_krw | W11: =AND(U11=0,T11="VERIFIED") -> FALSE
A12: GM-AD-SUPERNOVA-RISE-3 | B12: adidas Supernova Rise 3 | C12: DAILY | E12: ='05_v0.2_Benchmark'!O6 -> 4 | F12: ='05_v0.2_Benchmark'!P6 -> 5 | G12: ='05_v0.2_Benchmark'!Q6 -> 4 | H12: ='05_v0.2_Benchmark'!R6 -> 265.9 | I12: ='05_v0.2_Benchmark'!S6 -> 9.6 | J12: ='05_v0.2_Benchmark'!T6 -> NONE | K12: ='05_v0.2_Benchmark'!U6 -> NARROW | L12: ='05_v0.2_Benchmark'!V6 -> TRUE | ... N12: ='05_v0.2_Benchmark'!X6 -> ALL | O12: FIT_NARROW;OTHER | P12: HEAT_BREATHABILITY;HEEL_SLIP | Q12: 5 | R12: A_RTINGS | RTINGS_DIRECT | 공식/기존 Review Evidence 병행 | S12: PERF_NORM_v0.2 / USE_CASE_v0.2 / FIT_v0.2 | T12: VERIFIED | U12: =COUNTBLANK(E12:I12)+IF(J12="UNKNOWN",1,0)+IF(K12="UNKNOWN",1,0)+IF(L12="UNKNOWN",1,0)+IF(M12="UNKNOWN",1,0)+IF(N12="UNKNOWN",1,0) -> 0 | V12: =IF(U12=0,"",_xludf.TEXTJOIN(", ",TRUE,IF(E12="","cushion_score",""),IF(F12="","stability_score",""),IF(G12="","responsiveness_score",""),IF(H12="","weight_g",""),IF(I12="","drop_mm",""),IF(J12="UNKNOWN","plate_type",""),IF(K12="UNKNOWN","fit_width",""),IF(L12="UNKNOWN","wide_option",""),IF(M12="UNKNOWN","runner_level_fit",""),IF(N12="UNKNOWN","distance_fit",""))) | W12: =AND(U12=0,T12="VERIFIED") -> TRUE
A13: GM-AD-SUPERNOVA-EASE-BASE | B13: adidas Supernova Ease | C13: DAILY | J13: UNKNOWN | K13: UNKNOWN | L13: UNKNOWN | M13: BEGINNER | N13: UNKNOWN | Q13: 0 | R13: Official migrated + external review 0건 | S13: USE_CASE_MIGRATION_v0.1 / FIT_CAUTION_RULE_v0.1 | T13: DRAFT | U13: =COUNTBLANK(E13:I13)+IF(J13="UNKNOWN",1,0)+IF(K13="UNKNOWN",1,0)+IF(L13="UNKNOWN",1,0)+IF(M13="UNKNOWN",1,0)+IF(N13="UNKNOWN",1,0) -> 9 | V13: cushion_score, stability_score, responsiveness_score, weight_g, drop_mm, plate_type, fit_width, wide_option, distance_fit, msrp_krw | W13: =AND(U13=0,T13="VERIFIED") -> FALSE
A14: GM-AD-ADIZERO-SL-2 | B14: adidas Adizero SL 2 | C14: TEMPO | D14: DAILY | E14: ='05_v0.2_Benchmark'!O24 -> 4 | F14: ='05_v0.2_Benchmark'!P24 -> 2 | G14: ='05_v0.2_Benchmark'!Q24 -> 3 | H14: ='05_v0.2_Benchmark'!R24 -> 245 | I14: ='05_v0.2_Benchmark'!S24 -> 8.2 | J14: ='05_v0.2_Benchmark'!T24 -> NONE | K14: ='05_v0.2_Benchmark'!U24 -> STANDARD | L14: ='05_v0.2_Benchmark'!V24 -> TRUE | ... N14: ='05_v0.2_Benchmark'!X24 -> ALL | O14: FIT_NARROW;OTHER | P14: DURABILITY | Q14: 3 | R14: B_RUNREPEAT | RUNREPEAT_RELATIVE | 공식/기존 Review Evidence 병행 | S14: PERF_NORM_v0.2 / USE_CASE_v0.2 / FIT_v0.2 | T14: VERIFIED | U14: =COUNTBLANK(E14:I14)+IF(J14="UNKNOWN",1,0)+IF(K14="UNKNOWN",1,0)+IF(L14="UNKNOWN",1,0)+IF(M14="UNKNOWN",1,0)+IF(N14="UNKNOWN",1,0) -> 0 | V14: =IF(U14=0,"",_xludf.TEXTJOIN(", ",TRUE,IF(E14="","cushion_score",""),IF(F14="","stability_score",""),IF(G14="","responsiveness_score",""),IF(H14="","weight_g",""),IF(I14="","drop_mm",""),IF(J14="UNKNOWN","plate_type",""),IF(K14="UNKNOWN","fit_width",""),IF(L14="UNKNOWN","wide_option",""),IF(M14="UNKNOWN","runner_level_fit",""),IF(N14="UNKNOWN","distance_fit",""))) | W14: =AND(U14=0,T14="VERIFIED") -> TRUE
A15: GM-AD-ADIZERO-EVO-SL-BASE | B15: adidas Adizero EVO SL | C15: TEMPO | D15: DAILY | E15: ='05_v0.2_Benchmark'!O23 -> 4 | F15: ='05_v0.2_Benchmark'!P23 -> 4 | G15: ='05_v0.2_Benchmark'!Q23 -> 4 | H15: ='05_v0.2_Benchmark'!R23 -> 220 | I15: ='05_v0.2_Benchmark'!S23 -> 6.7 | J15: ='05_v0.2_Benchmark'!T23 -> OTHER | K15: ='05_v0.2_Benchmark'!U23 -> STANDARD | L15: ='05_v0.2_Benchmark'!V23 -> FALSE | ... N15: ='05_v0.2_Benchmark'!X23 -> ALL | O15: OTHER | P15: BLISTER;DURABILITY | Q15: 1 | R15: A_RTINGS | RTINGS_COMPOSITE | 공식/기존 Review Evidence 병행 | S15: PERF_NORM_v0.2 / USE_CASE_v0.2 / FIT_v0.2 | T15: VERIFIED | U15: =COUNTBLANK(E15:I15)+IF(J15="UNKNOWN",1,0)+IF(K15="UNKNOWN",1,0)+IF(L15="UNKNOWN",1,0)+IF(M15="UNKNOWN",1,0)+IF(N15="UNKNOWN",1,0) -> 0 | V15: =IF(U15=0,"",_xludf.TEXTJOIN(", ",TRUE,IF(E15="","cushion_score",""),IF(F15="","stability_score",""),IF(G15="","responsiveness_score",""),IF(H15="","weight_g",""),IF(I15="","drop_mm",""),IF(J15="UNKNOWN","plate_type",""),IF(K15="UNKNOWN","fit_width",""),IF(L15="UNKNOWN","wide_option",""),IF(M15="UNKNOWN","runner_level_fit",""),IF(N15="UNKNOWN","distance_fit",""))) | W15: =AND(U15=0,T15="VERIFIED") -> TRUE
A16: GM-AD-ADIZERO-ADIOS-PRO-4 | B16: adidas Adizero Adios Pro 4 | C16: RACE | D16: DAILY;TEMPO | E16: ='05_v0.2_Benchmark'!O31 -> 4 | F16: ='05_v0.2_Benchmark'!P31 -> 3 | G16: ='05_v0.2_Benchmark'!Q31 -> 5 | H16: ='05_v0.2_Benchmark'!R31 -> 197.5 | I16: ='05_v0.2_Benchmark'!S31 -> 7 | J16: ='05_v0.2_Benchmark'!T31 -> CARBON | K16: ='05_v0.2_Benchmark'!U31 -> NARROW | L16: ='05_v0.2_Benchmark'!V31 -> FALSE | ... N16: ='05_v0.2_Benchmark'!X31 -> LONG | Q16: 0 | R16: A_RTINGS | RTINGS_DIRECT | 공식/기존 Review Evidence 병행 | S16: PERF_NORM_v0.2 / USE_CASE_v0.2 / FIT_v0.2 | T16: VERIFIED | U16: =COUNTBLANK(E16:I16)+IF(J16="UNKNOWN",1,0)+IF(K16="UNKNOWN",1,0)+IF(L16="UNKNOWN",1,0)+IF(M16="UNKNOWN",1,0)+IF(N16="UNKNOWN",1,0) -> 0 | V16: =IF(U16=0,"",_xludf.TEXTJOIN(", ",TRUE,IF(E16="","cushion_score",""),IF(F16="","stability_score",""),IF(G16="","responsiveness_score",""),IF(H16="","weight_g",""),IF(I16="","drop_mm",""),IF(J16="UNKNOWN","plate_type",""),IF(K16="UNKNOWN","fit_width",""),IF(L16="UNKNOWN","wide_option",""),IF(M16="UNKNOWN","runner_level_fit",""),IF(N16="UNKNOWN","distance_fit",""))) | W16: =AND(U16=0,T16="VERIFIED") -> TRUE
A17: GM-AD-DURAMO-SL-2 | B17: adidas Duramo SL 2 | C17: DAILY | E17: ='05_v0.2_Benchmark'!O5 | F17: ='05_v0.2_Benchmark'!P5 | G17: ='05_v0.2_Benchmark'!Q5 | H17: ='05_v0.2_Benchmark'!R5 -> 291 | I17: ='05_v0.2_Benchmark'!S5 -> 9 | J17: ='05_v0.2_Benchmark'!T5 -> NONE | K17: ='05_v0.2_Benchmark'!U5 -> STANDARD | L17: ='05_v0.2_Benchmark'!V5 -> TRUE | ... N17: ='05_v0.2_Benchmark'!X5 -> ALL | O17: FIT_NARROW;OTHER | P17: HEAT_BREATHABILITY | Q17: 3 | R17: C_OFFICIAL_ONLY | OFFICIAL_FACT_ONLY | 공식/기존 Review Evidence 병행 | S17: PERF_NORM_v0.2 / USE_CASE_v0.2 / FIT_v0.2 | T17: DRAFT | U17: =COUNTBLANK(E17:I17)+IF(J17="UNKNOWN",1,0)+IF(K17="UNKNOWN",1,0)+IF(L17="UNKNOWN",1,0)+IF(M17="UNKNOWN",1,0)+IF(N17="UNKNOWN",1,0) -> 3 | V17: =IF(U17=0,"",_xludf.TEXTJOIN(", ",TRUE,IF(E17="","cushion_score",""),IF(F17="","stability_score",""),IF(G17="","responsiveness_score",""),IF(H17="","weight_g",""),IF(I17="","drop_mm",""),IF(J17="UNKNOWN","plate_type",""),IF(K17="UNKNOWN","fit_width",""),IF(L17="UNKNOWN","wide_option",""),IF(M17="UNKNOWN","runner_level_fit",""),IF(N17="UNKNOWN","distance_fit",""))) -> #NAME? | W17: =AND(U17=0,T17="VERIFIED") -> FALSE
A18: GM-AD-DURAMO-SPEED-2 | B18: adidas Duramo Speed 2 | C18: DAILY | J18: UNKNOWN | K18: UNKNOWN | L18: UNKNOWN | M18: BEGINNER | N18: UNKNOWN | O18: OTHER;STABILITY_LOW | P18: BLISTER | Q18: 2 | R18: Official migrated + external review 2건 | S18: USE_CASE_MIGRATION_v0.1 / FIT_CAUTION_RULE_v0.1 | T18: DRAFT | U18: =COUNTBLANK(E18:I18)+IF(J18="UNKNOWN",1,0)+IF(K18="UNKNOWN",1,0)+IF(L18="UNKNOWN",1,0)+IF(M18="UNKNOWN",1,0)+IF(N18="UNKNOWN",1,0) -> 9 | V18: cushion_score, stability_score, responsiveness_score, weight_g, drop_mm, plate_type, fit_width, wide_option, distance_fit | W18: =AND(U18=0,T18="VERIFIED") -> FALSE
A19: GM-NB-FRESH-FOAM-X-1080-V15 | B19: New Balance Fresh Foam X 1080 v15 | C19: LONG | D19: DAILY | E19: ='05_v0.2_Benchmark'!O9 -> 4 | F19: ='05_v0.2_Benchmark'!P9 -> 4 | G19: ='05_v0.2_Benchmark'!Q9 -> 4 | H19: ='05_v0.2_Benchmark'!R9 -> 250.3 | I19: ='05_v0.2_Benchmark'!S9 -> 7.8 | J19: ='05_v0.2_Benchmark'!T9 -> NONE | K19: ='05_v0.2_Benchmark'!U9 -> NARROW | L19: ='05_v0.2_Benchmark'!V9 -> TRUE | ... N19: ='05_v0.2_Benchmark'!X9 -> LONG | O19: FIT_NARROW;OTHER | P19: HEAT_BREATHABILITY | Q19: 5 | R19: A_RTINGS | RTINGS_DIRECT | 공식/기존 Review Evidence 병행 | S19: PERF_NORM_v0.2 / USE_CASE_v0.2 / FIT_v0.2 | T19: VERIFIED | U19: =COUNTBLANK(E19:I19)+IF(J19="UNKNOWN",1,0)+IF(K19="UNKNOWN",1,0)+IF(L19="UNKNOWN",1,0)+IF(M19="UNKNOWN",1,0)+IF(N19="UNKNOWN",1,0) -> 0 | V19: =IF(U19=0,"",_xludf.TEXTJOIN(", ",TRUE,IF(E19="","cushion_score",""),IF(F19="","stability_score",""),IF(G19="","responsiveness_score",""),IF(H19="","weight_g",""),IF(I19="","drop_mm",""),IF(J19="UNKNOWN","plate_type",""),IF(K19="UNKNOWN","fit_width",""),IF(L19="UNKNOWN","wide_option",""),IF(M19="UNKNOWN","runner_level_fit",""),IF(N19="UNKNOWN","distance_fit",""))) | W19: =AND(U19=0,T19="VERIFIED") -> TRUE
A20: GM-NB-FRESH-FOAM-X-880-V15 | B20: New Balance Fresh Foam X 880 v15 | C20: DAILY | E20: ='05_v0.2_Benchmark'!O10 -> 4 | F20: ='05_v0.2_Benchmark'!P10 -> 5 | G20: ='05_v0.2_Benchmark'!Q10 -> 4 | H20: ='05_v0.2_Benchmark'!R10 -> 286.6 | I20: ='05_v0.2_Benchmark'!S10 -> 7.3 | J20: ='05_v0.2_Benchmark'!T10 -> NONE | K20: ='05_v0.2_Benchmark'!U10 -> STANDARD | L20: ='05_v0.2_Benchmark'!V10 -> TRUE | ... N20: ='05_v0.2_Benchmark'!X10 -> ALL | O20: FIT_NARROW;FIT_WIDE;OTHER | P20: FOREFOOT_PRESSURE | Q20: 4 | R20: A_RTINGS | RTINGS_DIRECT | 공식/기존 Review Evidence 병행 | S20: PERF_NORM_v0.2 / USE_CASE_v0.2 / FIT_v0.2 | T20: VERIFIED | U20: =COUNTBLANK(E20:I20)+IF(J20="UNKNOWN",1,0)+IF(K20="UNKNOWN",1,0)+IF(L20="UNKNOWN",1,0)+IF(M20="UNKNOWN",1,0)+IF(N20="UNKNOWN",1,0) -> 0 | V20: =IF(U20=0,"",_xludf.TEXTJOIN(", ",TRUE,IF(E20="","cushion_score",""),IF(F20="","stability_score",""),IF(G20="","responsiveness_score",""),IF(H20="","weight_g",""),IF(I20="","drop_mm",""),IF(J20="UNKNOWN","plate_type",""),IF(K20="UNKNOWN","fit_width",""),IF(L20="UNKNOWN","wide_option",""),IF(M20="UNKNOWN","runner_level_fit",""),IF(N20="UNKNOWN","distance_fit",""))) | W20: =AND(U20=0,T20="VERIFIED") -> TRUE
A21: GM-NB-FRESH-FOAM-X-860-V15 | B21: New Balance Fresh Foam X 860 v15 | C21: STABILITY | E21: ='05_v0.2_Benchmark'!O16 -> 4 | F21: ='05_v0.2_Benchmark'!P16 -> 5 | G21: ='05_v0.2_Benchmark'!Q16 -> 4 | H21: ='05_v0.2_Benchmark'!R16 -> 329.3 | I21: ='05_v0.2_Benchmark'!S16 -> 6 | J21: ='05_v0.2_Benchmark'!T16 -> OTHER | K21: ='05_v0.2_Benchmark'!U16 -> NARROW | L21: ='05_v0.2_Benchmark'!V16 -> TRUE | ... N21: ='05_v0.2_Benchmark'!X16 -> ALL | O21: FIT_NARROW;OTHER;STABILITY_LOW | P21: BLISTER;FOREFOOT_PRESSURE | Q21: 4 | R21: A_RTINGS | RTINGS_DIRECT | 공식/기존 Review Evidence 병행 | S21: PERF_NORM_v0.2 / USE_CASE_v0.2 / FIT_v0.2 | T21: VERIFIED | U21: =COUNTBLANK(E21:I21)+IF(J21="UNKNOWN",1,0)+IF(K21="UNKNOWN",1,0)+IF(L21="UNKNOWN",1,0)+IF(M21="UNKNOWN",1,0)+IF(N21="UNKNOWN",1,0) -> 0 | V21: =IF(U21=0,"",_xludf.TEXTJOIN(", ",TRUE,IF(E21="","cushion_score",""),IF(F21="","stability_score",""),IF(G21="","responsiveness_score",""),IF(H21="","weight_g",""),IF(I21="","drop_mm",""),IF(J21="UNKNOWN","plate_type",""),IF(K21="UNKNOWN","fit_width",""),IF(L21="UNKNOWN","wide_option",""),IF(M21="UNKNOWN","runner_level_fit",""),IF(N21="UNKNOWN","distance_fit",""))) | W21: =AND(U21=0,T21="VERIFIED") -> TRUE
A22: GM-NB-FUELCELL-SUPERCOMP-ELITE-V5 | B22: New Balance FuelCell SuperComp Elite v5 | C22: RACE | E22: ='05_v0.2_Benchmark'!O27 -> 4 | F22: ='05_v0.2_Benchmark'!P27 -> 3 | G22: ='05_v0.2_Benchmark'!Q27 -> 5 | H22: ='05_v0.2_Benchmark'!R27 -> 200.5 | I22: ='05_v0.2_Benchmark'!S27 -> 8.9 | J22: ='05_v0.2_Benchmark'!T27 -> CARBON | K22: ='05_v0.2_Benchmark'!U27 -> NARROW | L22: ='05_v0.2_Benchmark'!V27 -> TRUE | ... N22: ='05_v0.2_Benchmark'!X27 -> LONG | O22: AGGRESSIVE_RIDE;FIT_NARROW;OTHER;STABILITY_LOW | P22: HEAT_BREATHABILITY | Q22: 6 | R22: A_RTINGS | RTINGS_DIRECT | 공식/기존 Review Evidence 병행 | S22: PERF_NORM_v0.2 / USE_CASE_v0.2 / FIT_v0.2 | T22: VERIFIED | U22: =COUNTBLANK(E22:I22)+IF(J22="UNKNOWN",1,0)+IF(K22="UNKNOWN",1,0)+IF(L22="UNKNOWN",1,0)+IF(M22="UNKNOWN",1,0)+IF(N22="UNKNOWN",1,0) -> 0 | V22: =IF(U22=0,"",_xludf.TEXTJOIN(", ",TRUE,IF(E22="","cushion_score",""),IF(F22="","stability_score",""),IF(G22="","responsiveness_score",""),IF(H22="","weight_g",""),IF(I22="","drop_mm",""),IF(J22="UNKNOWN","plate_type",""),IF(K22="UNKNOWN","fit_width",""),IF(L22="UNKNOWN","wide_option",""),IF(M22="UNKNOWN","runner_level_fit",""),IF(N22="UNKNOWN","distance_fit",""))) | W22: =AND(U22=0,T22="VERIFIED") -> TRUE
A23: GM-HK-CLIFTON-10 | B23: HOKA Clifton 10 | C23: DAILY | J23: UNKNOWN | K23: NARROW | L23: UNKNOWN | M23: UNKNOWN | N23: UNKNOWN | O23: FIT_NARROW;OTHER | P23: BLISTER;HEEL_SLIP | Q23: 7 | R23: Official migrated + external review 7건 | S23: USE_CASE_MIGRATION_v0.1 / FIT_CAUTION_RULE_v0.1 | T23: DRAFT | U23: =COUNTBLANK(E23:I23)+IF(J23="UNKNOWN",1,0)+IF(K23="UNKNOWN",1,0)+IF(L23="UNKNOWN",1,0)+IF(M23="UNKNOWN",1,0)+IF(N23="UNKNOWN",1,0) -> 9 | V23: cushion_score, stability_score, responsiveness_score, weight_g, drop_mm, plate_type, wide_option, runner_level_fit, distance_fit | W23: =AND(U23=0,T23="VERIFIED") -> FALSE
A24: GM-HK-BONDI-9 | B24: HOKA Bondi 9 | C24: LONG | J24: UNKNOWN | K24: NARROW | L24: UNKNOWN | M24: UNKNOWN | N24: UNKNOWN | O24: FIT_NARROW;HEAVY;OTHER | P24: BLISTER;DURABILITY;HEEL_SLIP | Q24: 5 | R24: Official migrated + external review 5건 | S24: USE_CASE_MIGRATION_v0.1 / FIT_CAUTION_RULE_v0.1 | T24: DRAFT | U24: =COUNTBLANK(E24:I24)+IF(J24="UNKNOWN",1,0)+IF(K24="UNKNOWN",1,0)+IF(L24="UNKNOWN",1,0)+IF(M24="UNKNOWN",1,0)+IF(N24="UNKNOWN",1,0) -> 9 | V24: cushion_score, stability_score, responsiveness_score, weight_g, drop_mm, plate_type, wide_option, runner_level_fit, distance_fit | W24: =AND(U24=0,T24="VERIFIED") -> FALSE
A25: GM-HK-ARAHI-8 | B25: HOKA Arahi 8 | C25: STABILITY | J25: UNKNOWN | K25: NARROW | L25: UNKNOWN | M25: UNKNOWN | N25: UNKNOWN | O25: FIT_NARROW;OTHER;STABILITY_LOW | P25: DURABILITY | Q25: 6 | R25: Official migrated + external review 6건 | S25: USE_CASE_MIGRATION_v0.1 / FIT_CAUTION_RULE_v0.1 | T25: DRAFT | U25: =COUNTBLANK(E25:I25)+IF(J25="UNKNOWN",1,0)+IF(K25="UNKNOWN",1,0)+IF(L25="UNKNOWN",1,0)+IF(M25="UNKNOWN",1,0)+IF(N25="UNKNOWN",1,0) -> 9 | V25: cushion_score, stability_score, responsiveness_score, weight_g, drop_mm, plate_type, wide_option, runner_level_fit, distance_fit | W25: =AND(U25=0,T25="VERIFIED") -> FALSE
A26: GM-HK-MACH-7 | B26: HOKA Mach 7 | C26: TEMPO | D26: DAILY | J26: UNKNOWN | K26: NARROW | L26: UNKNOWN | M26: UNKNOWN | N26: UNKNOWN | O26: FIT_NARROW;OTHER | Q26: 4 | R26: Official migrated + external review 4건 | S26: USE_CASE_MIGRATION_v0.1 / FIT_CAUTION_RULE_v0.1 | T26: DRAFT | U26: =COUNTBLANK(E26:I26)+IF(J26="UNKNOWN",1,0)+IF(K26="UNKNOWN",1,0)+IF(L26="UNKNOWN",1,0)+IF(M26="UNKNOWN",1,0)+IF(N26="UNKNOWN",1,0) -> 9 | V26: cushion_score, stability_score, responsiveness_score, weight_g, drop_mm, plate_type, wide_option, runner_level_fit, distance_fit | W26: =AND(U26=0,T26="VERIFIED") -> FALSE
A27: GM-HK-CIELO-X1-3_0 | B27: HOKA Cielo X1 3.0 | C27: RACE | J27: CARBON | K27: UNKNOWN | L27: UNKNOWN | M27: UNKNOWN | N27: UNKNOWN | O27: FIT_NARROW;STABILITY_LOW | Q27: 2 | R27: Official migrated + external review 2건 | S27: USE_CASE_MIGRATION_v0.1 / FIT_CAUTION_RULE_v0.1 | T27: DRAFT | U27: =COUNTBLANK(E27:I27)+IF(J27="UNKNOWN",1,0)+IF(K27="UNKNOWN",1,0)+IF(L27="UNKNOWN",1,0)+IF(M27="UNKNOWN",1,0)+IF(N27="UNKNOWN",1,0) -> 9 | V27: cushion_score, stability_score, responsiveness_score, weight_g, drop_mm, fit_width, wide_option, runner_level_fit, distance_fit | W27: =AND(U27=0,T27="VERIFIED") -> FALSE
A28: GM-AS-GEL-KAYANO-33 | B28: ASICS GEL-KAYANO 33 | C28: STABILITY | D28: LONG | E28: ='05_v0.2_Benchmark'!O14 -> 4 | F28: ='05_v0.2_Benchmark'!P14 -> 5 | G28: ='05_v0.2_Benchmark'!Q14 -> 3 | H28: ='05_v0.2_Benchmark'!R14 -> 295.9 | I28: ='05_v0.2_Benchmark'!S14 -> 11.1 | J28: ='05_v0.2_Benchmark'!T14 -> NONE | K28: ='05_v0.2_Benchmark'!U14 -> STANDARD | L28: ='05_v0.2_Benchmark'!V14 -> TRUE | ... N28: ='05_v0.2_Benchmark'!X14 -> ALL | Q28: 0 | R28: A_RTINGS | RTINGS_DIRECT | 공식/기존 Review Evidence 병행 | S28: PERF_NORM_v0.2 / USE_CASE_v0.2 / FIT_v0.2 | T28: VERIFIED | U28: =COUNTBLANK(E28:I28)+IF(J28="UNKNOWN",1,0)+IF(K28="UNKNOWN",1,0)+IF(L28="UNKNOWN",1,0)+IF(M28="UNKNOWN",1,0)+IF(N28="UNKNOWN",1,0) -> 0 | V28: =IF(U28=0,"",_xludf.TEXTJOIN(", ",TRUE,IF(E28="","cushion_score",""),IF(F28="","stability_score",""),IF(G28="","responsiveness_score",""),IF(H28="","weight_g",""),IF(I28="","drop_mm",""),IF(J28="UNKNOWN","plate_type",""),IF(K28="UNKNOWN","fit_width",""),IF(L28="UNKNOWN","wide_option",""),IF(M28="UNKNOWN","runner_level_fit",""),IF(N28="UNKNOWN","distance_fit",""))) | W28: =AND(U28=0,T28="VERIFIED") -> TRUE
A29: GM-AS-GEL-KAYANO-32 | B29: ASICS GEL-KAYANO 32 | C29: STABILITY | D29: LONG | J29: UNKNOWN | K29: UNKNOWN | L29: UNKNOWN | M29: UNKNOWN | N29: LONG | Q29: 0 | R29: Official migrated + external review 0건 | S29: USE_CASE_MIGRATION_v0.1 / FIT_CAUTION_RULE_v0.1 | T29: DRAFT | U29: =COUNTBLANK(E29:I29)+IF(J29="UNKNOWN",1,0)+IF(K29="UNKNOWN",1,0)+IF(L29="UNKNOWN",1,0)+IF(M29="UNKNOWN",1,0)+IF(N29="UNKNOWN",1,0) -> 9 | V29: cushion_score, stability_score, responsiveness_score, weight_g, drop_mm, plate_type, fit_width, wide_option, runner_level_fit | W29: =AND(U29=0,T29="VERIFIED") -> FALSE
A30: GM-AS-GEL-NIMBUS-28 | B30: ASICS GEL-NIMBUS 28 | C30: LONG | D30: DAILY | E30: ='05_v0.2_Benchmark'!O7 -> 5 | F30: ='05_v0.2_Benchmark'!P7 -> 5 | G30: ='05_v0.2_Benchmark'!Q7 -> 3 | H30: ='05_v0.2_Benchmark'!R7 -> 272.9 | I30: ='05_v0.2_Benchmark'!S7 -> 6.4 | J30: ='05_v0.2_Benchmark'!T7 -> NONE | K30: ='05_v0.2_Benchmark'!U7 -> NARROW | L30: ='05_v0.2_Benchmark'!V7 -> TRUE | ... N30: ='05_v0.2_Benchmark'!X7 -> LONG | O30: FIT_NARROW;HEAVY;OTHER | Q30: 4 | R30: A_RTINGS | RTINGS_DIRECT | 공식/기존 Review Evidence 병행 | S30: PERF_NORM_v0.2 / USE_CASE_v0.2 / FIT_v0.2 | T30: VERIFIED | U30: =COUNTBLANK(E30:I30)+IF(J30="UNKNOWN",1,0)+IF(K30="UNKNOWN",1,0)+IF(L30="UNKNOWN",1,0)+IF(M30="UNKNOWN",1,0)+IF(N30="UNKNOWN",1,0) -> 0 | V30: =IF(U30=0,"",_xludf.TEXTJOIN(", ",TRUE,IF(E30="","cushion_score",""),IF(F30="","stability_score",""),IF(G30="","responsiveness_score",""),IF(H30="","weight_g",""),IF(I30="","drop_mm",""),IF(J30="UNKNOWN","plate_type",""),IF(K30="UNKNOWN","fit_width",""),IF(L30="UNKNOWN","wide_option",""),IF(M30="UNKNOWN","runner_level_fit",""),IF(N30="UNKNOWN","distance_fit",""))) | W30: =AND(U30=0,T30="VERIFIED") -> TRUE
A31: GM-AS-NOVABLAST-5 | B31: ASICS NOVABLAST 5 | C31: DAILY | E31: ='05_v0.2_Benchmark'!O2 -> 5 | F31: ='05_v0.2_Benchmark'!P2 -> 4 | G31: ='05_v0.2_Benchmark'!Q2 -> 4 | H31: ='05_v0.2_Benchmark'!R2 -> 248.2 | I31: ='05_v0.2_Benchmark'!S2 -> 8.2 | J31: ='05_v0.2_Benchmark'!T2 -> NONE | K31: ='05_v0.2_Benchmark'!U2 -> STANDARD | L31: ='05_v0.2_Benchmark'!V2 -> TRUE | ... N31: ='05_v0.2_Benchmark'!X2 -> ALL | O31: AGGRESSIVE_RIDE;FIT_NARROW;HEAVY;OTHER | P31: DURABILITY;HEAT_BREATHABILITY;WET_GRIP | Q31: 8 | R31: A_RTINGS | RTINGS_DIRECT | 공식/기존 Review Evidence 병행 | S31: PERF_NORM_v0.2 / USE_CASE_v0.2 / FIT_v0.2 | T31: VERIFIED | U31: =COUNTBLANK(E31:I31)+IF(J31="UNKNOWN",1,0)+IF(K31="UNKNOWN",1,0)+IF(L31="UNKNOWN",1,0)+IF(M31="UNKNOWN",1,0)+IF(N31="UNKNOWN",1,0) -> 0 | V31: =IF(U31=0,"",_xludf.TEXTJOIN(", ",TRUE,IF(E31="","cushion_score",""),IF(F31="","stability_score",""),IF(G31="","responsiveness_score",""),IF(H31="","weight_g",""),IF(I31="","drop_mm",""),IF(J31="UNKNOWN","plate_type",""),IF(K31="UNKNOWN","fit_width",""),IF(L31="UNKNOWN","wide_option",""),IF(M31="UNKNOWN","runner_level_fit",""),IF(N31="UNKNOWN","distance_fit",""))) | W31: =AND(U31=0,T31="VERIFIED") -> TRUE
A32: GM-AS-SUPERBLAST-2 | B32: ASICS SUPERBLAST 2 | C32: TEMPO | D32: LONG | J32: NONE | K32: UNKNOWN | L32: UNKNOWN | M32: UNKNOWN | N32: LONG | O32: FIT_NARROW;OTHER | P32: BLISTER | Q32: 2 | R32: Official migrated + external review 2건 | S32: USE_CASE_MIGRATION_v0.1 / FIT_CAUTION_RULE_v0.1 | T32: DRAFT | U32: =COUNTBLANK(E32:I32)+IF(J32="UNKNOWN",1,0)+IF(K32="UNKNOWN",1,0)+IF(L32="UNKNOWN",1,0)+IF(M32="UNKNOWN",1,0)+IF(N32="UNKNOWN",1,0) -> 8 | V32: cushion_score, stability_score, responsiveness_score, weight_g, drop_mm, fit_width, wide_option, runner_level_fit | W32: =AND(U32=0,T32="VERIFIED") -> FALSE
A33: GM-AS-SUPERBLAST-3 | B33: ASICS SUPERBLAST 3 | C33: TEMPO | D33: LONG | E33: ='05_v0.2_Benchmark'!O20 -> 5 | F33: ='05_v0.2_Benchmark'!P20 -> 4 | G33: ='05_v0.2_Benchmark'!Q20 -> 4 | H33: ='05_v0.2_Benchmark'!R20 -> 232.6 | I33: ='05_v0.2_Benchmark'!S20 -> 7.1 | J33: ='05_v0.2_Benchmark'!T20 -> NONE | K33: ='05_v0.2_Benchmark'!U20 -> NARROW | L33: ='05_v0.2_Benchmark'!V20 -> FALSE | ... N33: ='05_v0.2_Benchmark'!X20 -> ALL | O33: FIT_NARROW;STABILITY_LOW | Q33: 1 | R33: A_RTINGS | RTINGS_COMPOSITE | 공식/기존 Review Evidence 병행 | S33: PERF_NORM_v0.2 / USE_CASE_v0.2 / FIT_v0.2 | T33: VERIFIED | U33: =COUNTBLANK(E33:I33)+IF(J33="UNKNOWN",1,0)+IF(K33="UNKNOWN",1,0)+IF(L33="UNKNOWN",1,0)+IF(M33="UNKNOWN",1,0)+IF(N33="UNKNOWN",1,0) -> 0 | V33: =IF(U33=0,"",_xludf.TEXTJOIN(", ",TRUE,IF(E33="","cushion_score",""),IF(F33="","stability_score",""),IF(G33="","responsiveness_score",""),IF(H33="","weight_g",""),IF(I33="","drop_mm",""),IF(J33="UNKNOWN","plate_type",""),IF(K33="UNKNOWN","fit_width",""),IF(L33="UNKNOWN","wide_option",""),IF(M33="UNKNOWN","runner_level_fit",""),IF(N33="UNKNOWN","distance_fit",""))) | W33: =AND(U33=0,T33="VERIFIED") -> TRUE
A34: GM-AS-METASPEED-SKY-TOKYO | B34: ASICS METASPEED SKY TOKYO | C34: RACE | E34: ='05_v0.2_Benchmark'!O25 -> 5 | F34: ='05_v0.2_Benchmark'!P25 -> 3 | G34: ='05_v0.2_Benchmark'!Q25 -> 4 | H34: ='05_v0.2_Benchmark'!R25 -> 157.3 | I34: ='05_v0.2_Benchmark'!S25 -> 4.7 | J34: ='05_v0.2_Benchmark'!T25 -> CARBON | K34: ='05_v0.2_Benchmark'!U25 -> NARROW | L34: ='05_v0.2_Benchmark'!V25 -> FALSE | ... N34: ='05_v0.2_Benchmark'!X25 -> LONG | O34: AGGRESSIVE_RIDE;OTHER;STABILITY_LOW | Q34: 2 | R34: A_RTINGS | RTINGS_COMPOSITE | 공식/기존 Review Evidence 병행 | S34: PERF_NORM_v0.2 / USE_CASE_v0.2 / FIT_v0.2 | T34: VERIFIED | U34: =COUNTBLANK(E34:I34)+IF(J34="UNKNOWN",1,0)+IF(K34="UNKNOWN",1,0)+IF(L34="UNKNOWN",1,0)+IF(M34="UNKNOWN",1,0)+IF(N34="UNKNOWN",1,0) -> 0 | V34: =IF(U34=0,"",_xludf.TEXTJOIN(", ",TRUE,IF(E34="","cushion_score",""),IF(F34="","stability_score",""),IF(G34="","responsiveness_score",""),IF(H34="","weight_g",""),IF(I34="","drop_mm",""),IF(J34="UNKNOWN","plate_type",""),IF(K34="UNKNOWN","fit_width",""),IF(L34="UNKNOWN","wide_option",""),IF(M34="UNKNOWN","runner_level_fit",""),IF(N34="UNKNOWN","distance_fit",""))) | W34: =AND(U34=0,T34="VERIFIED") -> TRUE
